ERROR:aiogram.dispatcher.dispatcher:Cause exception while getting updates.
Traceback (most recent call last):
  File "E:\Studing\Python Projects\Telegram Bots\SmilaBusTime\venv\Lib\site-packages\aiogram\dispatcher\dispatcher.py", line 381, in start_polling
    updates = await self.bot.get_updates(
              ^^^^^^^^^^^^^^^^^^^^^^^^^^^
  File "E:\Studing\Python Projects\Telegram Bots\SmilaBusTime\venv\Lib\site-packages\aiogram\bot\bot.py", line 110, in get_updates
    result = await self.request(api.Methods.GET_UPDATES, payload)
             ^^^^^^^^^^^^^^^^^^^^^^^^^^^^^^^^^^^^^^^^^^^^^^^^^^^^
  File "E:\Studing\Python Projects\Telegram Bots\SmilaBusTime\venv\Lib\site-packages\aiogram\bot\base.py", line 236, in request
    return await api.make_request(await self.get_session(), self.server, self.__token, method, data, files,
           ^^^^^^^^^^^^^^^^^^^^^^^^^^^^^^^^^^^^^^^^^^^^^^^^^^^^^^^^^^^^^^^^^^^^^^^^^^^^^^^^^^^^^^^^^^^^^^^^
  File "E:\Studing\Python Projects\Telegram Bots\SmilaBusTime\venv\Lib\site-packages\aiogram\bot\api.py", line 140, in make_request
    return check_result(method, response.content_type, response.status, await response.text())
           ^^^^^^^^^^^^^^^^^^^^^^^^^^^^^^^^^^^^^^^^^^^^^^^^^^^^^^^^^^^^^^^^^^^^^^^^^^^^^^^^^^^
  File "E:\Studing\Python Projects\Telegram Bots\SmilaBusTime\venv\Lib\site-packages\aiogram\bot\api.py", line 119, in check_result
    exceptions.ConflictError.detect(description)
  File "E:\Studing\Python Projects\Telegram Bots\SmilaBusTime\venv\Lib\site-packages\aiogram\utils\exceptions.py", line 140, in detect
    raise err(cls.text or description)
aiogram.utils.exceptions.TerminatedByOtherGetUpdates: Terminated by other getupdates request; make sure that only one bot instance is running
ERROR:aiogram.dispatcher.dispatcher:Cause exception while getting updates.
Traceback (most recent call last):
  File "E:\Studing\Python Projects\Telegram Bots\SmilaBusTime\venv\Lib\site-packages\aiogram\dispatcher\dispatcher.py", line 381, in start_polling
    updates = await self.bot.get_updates(
              ^^^^^^^^^^^^^^^^^^^^^^^^^^^
  File "E:\Studing\Python Projects\Telegram Bots\SmilaBusTime\venv\Lib\site-packages\aiogram\bot\bot.py", line 110, in get_updates
    result = await self.request(api.Methods.GET_UPDATES, payload)
             ^^^^^^^^^^^^^^^^^^^^^^^^^^^^^^^^^^^^^^^^^^^^^^^^^^^^
  File "E:\Studing\Python Projects\Telegram Bots\SmilaBusTime\venv\Lib\site-packages\aiogram\bot\base.py", line 236, in request
    return await api.make_request(await self.get_session(), self.server, self.__token, method, data, files,
           ^^^^^^^^^^^^^^^^^^^^^^^^^^^^^^^^^^^^^^^^^^^^^^^^^^^^^^^^^^^^^^^^^^^^^^^^^^^^^^^^^^^^^^^^^^^^^^^^
  File "E:\Studing\Python Projects\Telegram Bots\SmilaBusTime\venv\Lib\site-packages\aiogram\bot\api.py", line 140, in make_request
    return check_result(method, response.content_type, response.status, await response.text())
           ^^^^^^^^^^^^^^^^^^^^^^^^^^^^^^^^^^^^^^^^^^^^^^^^^^^^^^^^^^^^^^^^^^^^^^^^^^^^^^^^^^^
  File "E:\Studing\Python Projects\Telegram Bots\SmilaBusTime\venv\Lib\site-packages\aiogram\bot\api.py", line 119, in check_result
    exceptions.ConflictError.detect(description)
  File "E:\Studing\Python Projects\Telegram Bots\SmilaBusTime\venv\Lib\site-packages\aiogram\utils\exceptions.py", line 140, in detect
    raise err(cls.text or description)
aiogram.utils.exceptions.TerminatedByOtherGetUpdates: Terminated by other getupdates request; make sure that only one bot instance is running
ERROR:asyncio:Task exception was never retrieved
future: <Task finished name='Task-40' coro=<Dispatcher._process_polling_updates() done, defined at /usr/local/lib/python3.10/dist-packages/aiogram/dispatcher/dispatcher.py:407> exception=ObjectExpectedAsReplyMarkup('Object expected as reply markup')>
Traceback (most recent call last):
  File "/usr/local/lib/python3.10/dist-packages/aiogram/dispatcher/dispatcher.py", line 415, in _process_polling_updates
    for responses in itertools.chain.from_iterable(await self.process_updates(updates, fast)):
  File "/usr/local/lib/python3.10/dist-packages/aiogram/dispatcher/dispatcher.py", line 235, in process_updates
    return await asyncio.gather(*tasks)
  File "/usr/local/lib/python3.10/dist-packages/aiogram/dispatcher/handler.py", line 117, in notify
    response = await handler_obj.handler(*args, **partial_data)
  File "/usr/local/lib/python3.10/dist-packages/aiogram/dispatcher/dispatcher.py", line 256, in process_update
    return await self.message_handlers.notify(update.message)
  File "/usr/local/lib/python3.10/dist-packages/aiogram/dispatcher/handler.py", line 117, in notify
    response = await handler_obj.handler(*args, **partial_data)
  File "/home/vsevolod/Стільниця/SmilaBusTime_test/main.py", line 221, in process_message_from_admin
    await message.answer(text="Повідомлення отримано. Бажаєте прикріпити фото?",
  File "/usr/local/lib/python3.10/dist-packages/aiogram/types/message.py", line 438, in answer
    return await self.bot.send_message(
  File "/usr/local/lib/python3.10/dist-packages/aiogram/bot/bot.py", line 346, in send_message
    result = await self.request(api.Methods.SEND_MESSAGE, payload)
  File "/usr/local/lib/python3.10/dist-packages/aiogram/bot/base.py", line 236, in request
    return await api.make_request(await self.get_session(), self.server, self.__token, method, data, files,
  File "/usr/local/lib/python3.10/dist-packages/aiogram/bot/api.py", line 140, in make_request
    return check_result(method, response.content_type, response.status, await response.text())
  File "/usr/local/lib/python3.10/dist-packages/aiogram/bot/api.py", line 115, in check_result
    exceptions.BadRequest.detect(description)
  File "/usr/local/lib/python3.10/dist-packages/aiogram/utils/exceptions.py", line 140, in detect
    raise err(cls.text or description)
aiogram.utils.exceptions.ObjectExpectedAsReplyMarkup: Object expected as reply markup
ERROR:asyncio:Task exception was never retrieved
future: <Task finished name='Task-18' coro=<Dispatcher._process_polling_updates() done, defined at /usr/local/lib/python3.10/dist-packages/aiogram/dispatcher/dispatcher.py:407> exception=ObjectExpectedAsReplyMarkup('Object expected as reply markup')>
Traceback (most recent call last):
  File "/usr/local/lib/python3.10/dist-packages/aiogram/dispatcher/dispatcher.py", line 415, in _process_polling_updates
    for responses in itertools.chain.from_iterable(await self.process_updates(updates, fast)):
  File "/usr/local/lib/python3.10/dist-packages/aiogram/dispatcher/dispatcher.py", line 235, in process_updates
    return await asyncio.gather(*tasks)
  File "/usr/local/lib/python3.10/dist-packages/aiogram/dispatcher/handler.py", line 117, in notify
    response = await handler_obj.handler(*args, **partial_data)
  File "/usr/local/lib/python3.10/dist-packages/aiogram/dispatcher/dispatcher.py", line 256, in process_update
    return await self.message_handlers.notify(update.message)
  File "/usr/local/lib/python3.10/dist-packages/aiogram/dispatcher/handler.py", line 117, in notify
    response = await handler_obj.handler(*args, **partial_data)
  File "/home/vsevolod/Стільниця/SmilaBusTime_test/main.py", line 221, in process_message_from_admin
    await message.answer(text="Повідомлення отримано. Бажаєте прикріпити фото?",
  File "/usr/local/lib/python3.10/dist-packages/aiogram/types/message.py", line 438, in answer
    return await self.bot.send_message(
  File "/usr/local/lib/python3.10/dist-packages/aiogram/bot/bot.py", line 346, in send_message
    result = await self.request(api.Methods.SEND_MESSAGE, payload)
  File "/usr/local/lib/python3.10/dist-packages/aiogram/bot/base.py", line 236, in request
    return await api.make_request(await self.get_session(), self.server, self.__token, method, data, files,
  File "/usr/local/lib/python3.10/dist-packages/aiogram/bot/api.py", line 140, in make_request
    return check_result(method, response.content_type, response.status, await response.text())
  File "/usr/local/lib/python3.10/dist-packages/aiogram/bot/api.py", line 115, in check_result
    exceptions.BadRequest.detect(description)
  File "/usr/local/lib/python3.10/dist-packages/aiogram/utils/exceptions.py", line 140, in detect
    raise err(cls.text or description)
aiogram.utils.exceptions.ObjectExpectedAsReplyMarkup: Object expected as reply markup
ERROR:asyncio:Task exception was never retrieved
future: <Task finished name='Task-18' coro=<Dispatcher._process_polling_updates() done, defined at /usr/local/lib/python3.10/dist-packages/aiogram/dispatcher/dispatcher.py:407> exception=ObjectExpectedAsReplyMarkup('Object expected as reply markup')>
Traceback (most recent call last):
  File "/usr/local/lib/python3.10/dist-packages/aiogram/dispatcher/dispatcher.py", line 415, in _process_polling_updates
    for responses in itertools.chain.from_iterable(await self.process_updates(updates, fast)):
  File "/usr/local/lib/python3.10/dist-packages/aiogram/dispatcher/dispatcher.py", line 235, in process_updates
    return await asyncio.gather(*tasks)
  File "/usr/local/lib/python3.10/dist-packages/aiogram/dispatcher/handler.py", line 117, in notify
    response = await handler_obj.handler(*args, **partial_data)
  File "/usr/local/lib/python3.10/dist-packages/aiogram/dispatcher/dispatcher.py", line 256, in process_update
    return await self.message_handlers.notify(update.message)
  File "/usr/local/lib/python3.10/dist-packages/aiogram/dispatcher/handler.py", line 117, in notify
    response = await handler_obj.handler(*args, **partial_data)
  File "/home/vsevolod/Стільниця/SmilaBusTime_test/main.py", line 221, in process_message_from_admin
    await message.answer(text="Повідомлення отримано. Бажаєте прикріпити фото?",
  File "/usr/local/lib/python3.10/dist-packages/aiogram/types/message.py", line 438, in answer
    return await self.bot.send_message(
  File "/usr/local/lib/python3.10/dist-packages/aiogram/bot/bot.py", line 346, in send_message
    result = await self.request(api.Methods.SEND_MESSAGE, payload)
  File "/usr/local/lib/python3.10/dist-packages/aiogram/bot/base.py", line 236, in request
    return await api.make_request(await self.get_session(), self.server, self.__token, method, data, files,
  File "/usr/local/lib/python3.10/dist-packages/aiogram/bot/api.py", line 140, in make_request
    return check_result(method, response.content_type, response.status, await response.text())
  File "/usr/local/lib/python3.10/dist-packages/aiogram/bot/api.py", line 115, in check_result
    exceptions.BadRequest.detect(description)
  File "/usr/local/lib/python3.10/dist-packages/aiogram/utils/exceptions.py", line 140, in detect
    raise err(cls.text or description)
aiogram.utils.exceptions.ObjectExpectedAsReplyMarkup: Object expected as reply markup
ERROR:asyncio:Task exception was never retrieved
future: <Task finished name='Task-22' coro=<Dispatcher._process_polling_updates() done, defined at /usr/local/lib/python3.10/dist-packages/aiogram/dispatcher/dispatcher.py:407> exception=ObjectExpectedAsReplyMarkup('Object expected as reply markup')>
Traceback (most recent call last):
  File "/usr/local/lib/python3.10/dist-packages/aiogram/dispatcher/dispatcher.py", line 415, in _process_polling_updates
    for responses in itertools.chain.from_iterable(await self.process_updates(updates, fast)):
  File "/usr/local/lib/python3.10/dist-packages/aiogram/dispatcher/dispatcher.py", line 235, in process_updates
    return await asyncio.gather(*tasks)
  File "/usr/local/lib/python3.10/dist-packages/aiogram/dispatcher/handler.py", line 117, in notify
    response = await handler_obj.handler(*args, **partial_data)
  File "/usr/local/lib/python3.10/dist-packages/aiogram/dispatcher/dispatcher.py", line 256, in process_update
    return await self.message_handlers.notify(update.message)
  File "/usr/local/lib/python3.10/dist-packages/aiogram/dispatcher/handler.py", line 117, in notify
    response = await handler_obj.handler(*args, **partial_data)
  File "/home/vsevolod/Стільниця/SmilaBusTime_test/main.py", line 221, in process_message_from_admin
    await message.answer(text="Повідомлення отримано. Бажаєте прикріпити фото?",
  File "/usr/local/lib/python3.10/dist-packages/aiogram/types/message.py", line 438, in answer
    return await self.bot.send_message(
  File "/usr/local/lib/python3.10/dist-packages/aiogram/bot/bot.py", line 346, in send_message
    result = await self.request(api.Methods.SEND_MESSAGE, payload)
  File "/usr/local/lib/python3.10/dist-packages/aiogram/bot/base.py", line 236, in request
    return await api.make_request(await self.get_session(), self.server, self.__token, method, data, files,
  File "/usr/local/lib/python3.10/dist-packages/aiogram/bot/api.py", line 140, in make_request
    return check_result(method, response.content_type, response.status, await response.text())
  File "/usr/local/lib/python3.10/dist-packages/aiogram/bot/api.py", line 115, in check_result
    exceptions.BadRequest.detect(description)
  File "/usr/local/lib/python3.10/dist-packages/aiogram/utils/exceptions.py", line 140, in detect
    raise err(cls.text or description)
aiogram.utils.exceptions.ObjectExpectedAsReplyMarkup: Object expected as reply markup
ERROR:asyncio:Task exception was never retrieved
future: <Task finished name='Task-25' coro=<Dispatcher._process_polling_updates() done, defined at /usr/local/lib/python3.10/dist-packages/aiogram/dispatcher/dispatcher.py:407> exception=TypeError("Can not serialize value type: <class 'list'>\n headers: {}\n value: []")>
Traceback (most recent call last):
  File "/usr/local/lib/python3.10/dist-packages/aiohttp/formdata.py", line 145, in _gen_form_data
    part = payload.get_payload(
  File "/usr/local/lib/python3.10/dist-packages/aiohttp/payload.py", line 71, in get_payload
    return PAYLOAD_REGISTRY.get(data, *args, **kwargs)
  File "/usr/local/lib/python3.10/dist-packages/aiohttp/payload.py", line 118, in get
    raise LookupError()
aiohttp.payload.LookupError

The above exception was the direct cause of the following exception:

Traceback (most recent call last):
  File "/usr/local/lib/python3.10/dist-packages/aiogram/dispatcher/dispatcher.py", line 415, in _process_polling_updates
    for responses in itertools.chain.from_iterable(await self.process_updates(updates, fast)):
  File "/usr/local/lib/python3.10/dist-packages/aiogram/dispatcher/dispatcher.py", line 235, in process_updates
    return await asyncio.gather(*tasks)
  File "/usr/local/lib/python3.10/dist-packages/aiogram/dispatcher/handler.py", line 117, in notify
    response = await handler_obj.handler(*args, **partial_data)
  File "/usr/local/lib/python3.10/dist-packages/aiogram/dispatcher/dispatcher.py", line 256, in process_update
    return await self.message_handlers.notify(update.message)
  File "/usr/local/lib/python3.10/dist-packages/aiogram/dispatcher/handler.py", line 117, in notify
    response = await handler_obj.handler(*args, **partial_data)
  File "/home/vsevolod/Стільниця/SmilaBusTime_test/main.py", line 247, in process_message_from_admin
    await send_message_to_people(text, picture)
  File "/home/vsevolod/Стільниця/SmilaBusTime_test/main.py", line 67, in send_message_to_people
    await bot.send_photo(chat_id=str(user), photo=photo, caption=text, parse_mode="HTML")
  File "/usr/local/lib/python3.10/dist-packages/aiogram/bot/bot.py", line 565, in send_photo
    result = await self.request(api.Methods.SEND_PHOTO, payload, files)
  File "/usr/local/lib/python3.10/dist-packages/aiogram/bot/base.py", line 236, in request
    return await api.make_request(await self.get_session(), self.server, self.__token, method, data, files,
  File "/usr/local/lib/python3.10/dist-packages/aiogram/bot/api.py", line 139, in make_request
    async with session.post(url, data=req, **kwargs) as response:
  File "/usr/local/lib/python3.10/dist-packages/aiohttp/client.py", line 1141, in __aenter__
    self._resp = await self._coro
  File "/usr/local/lib/python3.10/dist-packages/aiohttp/client.py", line 508, in _request
    req = self._request_class(
  File "/usr/local/lib/python3.10/dist-packages/aiohttp/client_reqrep.py", line 313, in __init__
    self.update_body_from_data(data)
  File "/usr/local/lib/python3.10/dist-packages/aiohttp/client_reqrep.py", line 505, in update_body_from_data
    body = body()
  File "/usr/local/lib/python3.10/dist-packages/aiohttp/formdata.py", line 170, in __call__
    return self._gen_form_data()
  File "/usr/local/lib/python3.10/dist-packages/aiohttp/formdata.py", line 149, in _gen_form_data
    raise TypeError(
TypeError: Can not serialize value type: <class 'list'>
 headers: {}
 value: []
ERROR:asyncio:Task exception was never retrieved
future: <Task finished name='Task-27' coro=<Dispatcher._process_polling_updates() done, defined at /usr/local/lib/python3.10/dist-packages/aiogram/dispatcher/dispatcher.py:407> exception=TypeError("Can not serialize value type: <class 'list'>\n headers: {}\n value: []")>
Traceback (most recent call last):
  File "/usr/local/lib/python3.10/dist-packages/aiohttp/formdata.py", line 145, in _gen_form_data
    part = payload.get_payload(
  File "/usr/local/lib/python3.10/dist-packages/aiohttp/payload.py", line 71, in get_payload
    return PAYLOAD_REGISTRY.get(data, *args, **kwargs)
  File "/usr/local/lib/python3.10/dist-packages/aiohttp/payload.py", line 118, in get
    raise LookupError()
aiohttp.payload.LookupError

The above exception was the direct cause of the following exception:

Traceback (most recent call last):
  File "/usr/local/lib/python3.10/dist-packages/aiogram/dispatcher/dispatcher.py", line 415, in _process_polling_updates
    for responses in itertools.chain.from_iterable(await self.process_updates(updates, fast)):
  File "/usr/local/lib/python3.10/dist-packages/aiogram/dispatcher/dispatcher.py", line 235, in process_updates
    return await asyncio.gather(*tasks)
  File "/usr/local/lib/python3.10/dist-packages/aiogram/dispatcher/handler.py", line 117, in notify
    response = await handler_obj.handler(*args, **partial_data)
  File "/usr/local/lib/python3.10/dist-packages/aiogram/dispatcher/dispatcher.py", line 256, in process_update
    return await self.message_handlers.notify(update.message)
  File "/usr/local/lib/python3.10/dist-packages/aiogram/dispatcher/handler.py", line 117, in notify
    response = await handler_obj.handler(*args, **partial_data)
  File "/home/vsevolod/Стільниця/SmilaBusTime_test/main.py", line 247, in process_message_from_admin
    await send_message_to_people(text, picture)
  File "/home/vsevolod/Стільниця/SmilaBusTime_test/main.py", line 67, in send_message_to_people
    await bot.send_photo(chat_id=str(user), photo=photo, caption=text, parse_mode="HTML")
  File "/usr/local/lib/python3.10/dist-packages/aiogram/bot/bot.py", line 565, in send_photo
    result = await self.request(api.Methods.SEND_PHOTO, payload, files)
  File "/usr/local/lib/python3.10/dist-packages/aiogram/bot/base.py", line 236, in request
    return await api.make_request(await self.get_session(), self.server, self.__token, method, data, files,
  File "/usr/local/lib/python3.10/dist-packages/aiogram/bot/api.py", line 139, in make_request
    async with session.post(url, data=req, **kwargs) as response:
  File "/usr/local/lib/python3.10/dist-packages/aiohttp/client.py", line 1141, in __aenter__
    self._resp = await self._coro
  File "/usr/local/lib/python3.10/dist-packages/aiohttp/client.py", line 508, in _request
    req = self._request_class(
  File "/usr/local/lib/python3.10/dist-packages/aiohttp/client_reqrep.py", line 313, in __init__
    self.update_body_from_data(data)
  File "/usr/local/lib/python3.10/dist-packages/aiohttp/client_reqrep.py", line 505, in update_body_from_data
    body = body()
  File "/usr/local/lib/python3.10/dist-packages/aiohttp/formdata.py", line 170, in __call__
    return self._gen_form_data()
  File "/usr/local/lib/python3.10/dist-packages/aiohttp/formdata.py", line 149, in _gen_form_data
    raise TypeError(
TypeError: Can not serialize value type: <class 'list'>
 headers: {}
 value: []
ERROR:asyncio:Task exception was never retrieved
future: <Task finished name='Task-33' coro=<Dispatcher._process_polling_updates() done, defined at /usr/local/lib/python3.10/dist-packages/aiogram/dispatcher/dispatcher.py:407> exception=TypeError("Can not serialize value type: <class 'list'>\n headers: {}\n value: []")>
Traceback (most recent call last):
  File "/usr/local/lib/python3.10/dist-packages/aiohttp/formdata.py", line 145, in _gen_form_data
    part = payload.get_payload(
  File "/usr/local/lib/python3.10/dist-packages/aiohttp/payload.py", line 71, in get_payload
    return PAYLOAD_REGISTRY.get(data, *args, **kwargs)
  File "/usr/local/lib/python3.10/dist-packages/aiohttp/payload.py", line 118, in get
    raise LookupError()
aiohttp.payload.LookupError

The above exception was the direct cause of the following exception:

Traceback (most recent call last):
  File "/usr/local/lib/python3.10/dist-packages/aiogram/dispatcher/dispatcher.py", line 415, in _process_polling_updates
    for responses in itertools.chain.from_iterable(await self.process_updates(updates, fast)):
  File "/usr/local/lib/python3.10/dist-packages/aiogram/dispatcher/dispatcher.py", line 235, in process_updates
    return await asyncio.gather(*tasks)
  File "/usr/local/lib/python3.10/dist-packages/aiogram/dispatcher/handler.py", line 117, in notify
    response = await handler_obj.handler(*args, **partial_data)
  File "/usr/local/lib/python3.10/dist-packages/aiogram/dispatcher/dispatcher.py", line 256, in process_update
    return await self.message_handlers.notify(update.message)
  File "/usr/local/lib/python3.10/dist-packages/aiogram/dispatcher/handler.py", line 117, in notify
    response = await handler_obj.handler(*args, **partial_data)
  File "/home/vsevolod/Стільниця/SmilaBusTime_test/main.py", line 257, in final_message_sending
    await send_message_to_people(text, picture)
  File "/home/vsevolod/Стільниця/SmilaBusTime_test/main.py", line 69, in send_message_to_people
    await bot.send_photo(chat_id=str(user), photo=photo, caption=text, parse_mode="HTML")
  File "/usr/local/lib/python3.10/dist-packages/aiogram/bot/bot.py", line 565, in send_photo
    result = await self.request(api.Methods.SEND_PHOTO, payload, files)
  File "/usr/local/lib/python3.10/dist-packages/aiogram/bot/base.py", line 236, in request
    return await api.make_request(await self.get_session(), self.server, self.__token, method, data, files,
  File "/usr/local/lib/python3.10/dist-packages/aiogram/bot/api.py", line 139, in make_request
    async with session.post(url, data=req, **kwargs) as response:
  File "/usr/local/lib/python3.10/dist-packages/aiohttp/client.py", line 1141, in __aenter__
    self._resp = await self._coro
  File "/usr/local/lib/python3.10/dist-packages/aiohttp/client.py", line 508, in _request
    req = self._request_class(
  File "/usr/local/lib/python3.10/dist-packages/aiohttp/client_reqrep.py", line 313, in __init__
    self.update_body_from_data(data)
  File "/usr/local/lib/python3.10/dist-packages/aiohttp/client_reqrep.py", line 505, in update_body_from_data
    body = body()
  File "/usr/local/lib/python3.10/dist-packages/aiohttp/formdata.py", line 170, in __call__
    return self._gen_form_data()
  File "/usr/local/lib/python3.10/dist-packages/aiohttp/formdata.py", line 149, in _gen_form_data
    raise TypeError(
TypeError: Can not serialize value type: <class 'list'>
 headers: {}
 value: []
